Traceback (most recent call last):
  File "/System/Library/Frameworks/Python.framework/Versions/2.7/lib/python2.7/runpy.py", line 162, in _run_module_as_main
    "__main__", fname, loader, pkg_name)
  File "/System/Library/Frameworks/Python.framework/Versions/2.7/lib/python2.7/runpy.py", line 72, in _run_code
    exec code in run_globals
  File "/Users/Billy/BITS/SoMeToolkit/__main__.py", line 33, in <module>
    Collector.run(process, command)
  File "./src/controller.py", line 64, in run
    if process == 'insert': self.insert(command)
  File "./src/controller.py", line 175, in insert
    insertd.start()
  File "./src/daemon.py", line 132, in start
    self.run(api)
  File "./src/controller.py", line 39, in run
    self.scriptd.start()
  File "/Users/Billy/BITS/SoMeToolkit/src/twitter/mongoBatchInsert.py", line 242, in start
    inserted_ids_list = insert_tweet_list(mongoCollection, tweets_list, line_number, processedTweetsFile)
  File "/Users/Billy/BITS/SoMeToolkit/src/twitter/mongoBatchInsert.py", line 70, in insert_tweet_list
    mongo_error_code = data_db.error()
NameError: global name 'data_db' is not defined
